//global try catch wrapper
import * as express from 'express';
export const catchAsync =
    (
        fn: (
            req: express.Request,
            res: express.Response,
            next: express.NextFunction
        ) => Promise<unknown>
    ) =>
    async (
        req: express.Request,
        res: express.Response,
        next: express.NextFunction
    ) => {
        return Promise.resolve(fn(req, res, next)).catch((err) => next(err));
    };
